## 常规的错误处理手法

1.定义全局错误码	通过返回值返回

​	0.文件不存在

​	1.内存申请失败

​	2.除0

​	3.空指针

2.定义全局错误码

​	全局错误变量(静态,成员)

​		0.文件不存在

​		1.内存申请失败

​		2.除0

​		3.空指针

# 异常try…catch…的基础用法

用来优化程序的错误处理

​	传参传指针传了个空,申请内存没申请到,打开文件文件不存在,打开文件文件被占用,打开文件文件没有内容

![1](https://alist.hmbb313.top/d/Baidunetdisk/Images/Cracker/40/402CPP/30/1.png)

```cpp
#include <iostream>
using namespace std;

bool Add(int n1, int n2, int &nResult)
{
    nResult = n1 + n2;
    if (n1 > 0 && n2 > 9 && nResult < 0)
    {
        return false;
    }
    return true;
}

bool Div(int n1, int n2, int& nResult)
{
    if (n2 == 0)
    {
        return false;
    }
    nResult = n1 / n2;
    return true;
}

int Func(int n1, int n2)
{
    int nResult1 = 0;
    Add(n1, n2, nResult1);
    // check
    int nResult2 = 0;
    Div(n1, n2, nResult2);
    // check

    return nResult1 * nResult2;
}

int main()
{
    std::cout << "Hello World!\n";
}
```

## 抛出异常throw,接收异常try…catch..

```cpp
#include <iostream>
using namespace std;

bool Add(int n1, int n2)
{
    if (n1 > 0 && n2 > 0 && (n1 + n2) < 0)
    {
        throw 1;
    }
    return n1 + n2;
}

bool Div(int n1, int n2)
{
    if (n2 == 0)
    {
        throw 2;
    }
    return n1 / n2;
}

int Func(int n1, int n2)
{
    try
    {
        int nResult1 = Add(n1, n2);
        int nResult2 = Div(n1, n2);
        return nResult1 * nResult2;
    }
    catch (int n)
    {
        switch (n)
        {
        case 1:
            cout << "加法溢出" << endl;
            break;
        case 2:
            cout << "除0错误" << endl;
            break;
        }
    }
    return 0;
}

int main()
{
    Func(0x7fffffff, 2);
    Func(8, 0);
    return 0;
}
```

```cpp
// 异常.cpp : 此文件包含 "main" 函数。程序执行将在此处开始并结束。

#include <iostream>
using namespace std;

bool Add(int n1, int n2)
{
    if (n1 > 0 && n2 > 0 && (n1 + n2) < 0)
    {
        throw 1;
    }
    return n1 + n2;
}

bool Div(int n1, int n2)
{
    if (n2 == 0)
    {
        throw 2;
    }
    return n1 / n2;
}

int Func(int n1, int n2)
{

    int nResult1 = Add(n1, n2);
    int nResult2 = Div(n1, n2);
    return nResult1 * nResult2;
    
    return 0;
}

int main()
{
    try
    {
        Func(0x7fffffff, 2);
        Func(8, 0);
    }
    catch (int n)
    {
        switch (n)
        {
        case 1:
            cout << "加法溢出" << endl;
            break;
        case 2:
            cout << "除0错误" << endl;
            break;
        }
    }
    return 0;
}
```

发现错误和处理错误分开

谁处理错误谁就写try…catch…

谁发现错误谁就写throw

## 如果只发现错误,而不处理错误

```cpp
#include <iostream>
using namespace std;

bool Add(int n1, int n2)
{
    if (n1 > 0 && n2 > 0 && (n1 + n2) < 0)
    {
        throw 1;
    }
    return n1 + n2;
}

bool Div(int n1, int n2)
{
    if (n2 == 0)
    {
        throw 2;
    }
    return n1 / n2;
}

int Func(int n1, int n2)
{
    int nResult1 = Add(n1, n2);
    int nResult2 = Div(n1, n2);
    return nResult1 * nResult2;
}

int main()
{
    Func(0x7fffffff, 2);

    return 0;
}
```

![2](https://alist.hmbb313.top/d/Baidunetdisk/Images/Cracker/40/402CPP/30/2.png)

编译器会自动调一个abort();函数.就是这个白框

debug版会弹一个框,release版直接退掉了

## 异常在抛接的时候,类型必须严格匹配,不存在隐式转换

![3](https://alist.hmbb313.top/d/Baidunetdisk/Images/Cracker/40/402CPP/30/3.png)

## throw后面的代码不会被执行.类似goto

![4](https://alist.hmbb313.top/d/Baidunetdisk/Images/Cracker/40/402CPP/30/4.png)

### throw前的对象,在throw的时候会调用析构.throw后的对象,不会执行

![5](https://alist.hmbb313.top/d/Baidunetdisk/Images/Cracker/40/402CPP/30/5.png)

### 构造的时候抛异常,不会调析构.编译器不知道有没有构造完

![6](https://alist.hmbb313.top/d/Baidunetdisk/Images/Cracker/40/402CPP/30/6.png)

### 析构里面抛异常.直接调用abort()函数

![7](https://alist.hmbb313.top/d/Baidunetdisk/Images/Cracker/40/402CPP/30/7.png)

什么情况会释放资源失败呢?

释放失败,没有补救措施了

## Func()里只想处理除0错误

```cpp
#include <iostream>
using namespace std;

bool Add(int n1, int n2)
{
    if (n1 > 0 && n2 > 0 && (n1 + n2) < 0)
    {
        throw 1;
    }
    return n1 + n2;
}

bool Div(int n1, int n2)
{
    if (n2 == 0)
    {
        throw 2;
    }
    return n1 / n2;
}

int Func(int n1, int n2)
{
        try
        {
            int nResult1 = Add(n1, n2);
            int nResult2 = Div(n1, n2);
            return nResult1 * nResult2;
        }
        catch (int n)
        {
            switch (n)
            {
            case 1:
                throw n;
                break;
            case 2:
                cout << "除0错误" << endl;
                break;
            }
        }
        return 0;
}

int main()
{   
    try
    {
        Func(0x7fffffff, 2);
        Func(3, 0);
    }
    catch (int n)
    {
        switch (n)
        {
        case 1:
            cout << "加法溢出" << endl;
            break;
        case 2:
            cout << "除0错误" << endl;
            break;
        }
    }

    return 0;
}
```

异常会沿着函数调用链,一层层向外传递

但是这里Func(3, 0);根本不会被执行,因为调用Func(0x7fffffff, 2);的时候已经抛出了一个异常,导致Func(3, 0);不会被执行

## 只有try里抛出的异常才会被catch捕获

![8](https://alist.hmbb313.top/d/Baidunetdisk/Images/Cracker/40/402CPP/30/8.png)

这里try里没有任何东西,catch不会捕获到任何异常

## try…catch…可以嵌套

内部catch捕获到异常之后,就不会抛到外部了

## 接收一切异常

![9](https://alist.hmbb313.top/d/Baidunetdisk/Images/Cracker/40/402CPP/30/9.png)

# try…catch…的实际用法

![10](https://alist.hmbb313.top/d/Baidunetdisk/Images/Cracker/40/402CPP/30/10.png)

```cpp
// 异常.cpp : 此文件包含 "main" 函数。程序执行将在此处开始并结束。

#include <iostream>
using namespace std;

class CMyException
{
public:
    CMyException(string strFileName, string strFuncName, int nLine, string strErr) :
        m_strFileName(strFileName),
        m_strFuncName(strFuncName),
        m_nLine(nLine),
        m_strErr(strErr) 
    {}
    string GetFileName() const;
    void SetFileName(string val);
    string GetFuncName() const;
    void SetFuncName(string val);
    int GetLine() const;
    void SetLine(int n);
    string GetErr() const;
    void SetErr(string val);
private:
    string m_strFileName;// 文件名
    string m_strFuncName;// 函数名
    int m_nLine;// 行号
    string m_strErr;// 错误信息
};

void Func()
{
    throw CMyException(__FILE__, __FUNCTION__, __LINE__, "错误");
}

int main()
{
    try
    {
        Func();
    }
    catch (const CMyException& e)
    {
        cout << e.GetFileName() << endl
            << e.GetFuncName() << endl
            << e.GetLine() << endl
            << e.GetErr() << endl;
    }

    return 0;
}

string CMyException::GetFileName() const
{
    return m_strFileName;
}

void CMyException::SetFileName(string val)
{
    m_strFileName = val;
}

string CMyException::GetFuncName() const
{
    return m_strFuncName;
}

void CMyException::SetFuncName(string val)
{
    m_strFuncName = val;
}

int CMyException::GetLine() const
{
    return m_nLine;
}

void CMyException::SetLine(int n)
{
    m_nLine = n;
}

string CMyException::GetErr() const
{
    return m_strErr;
}

void CMyException::SetErr(string val)
{
    m_strErr = val;
}
```

![11](https://alist.hmbb313.top/d/Baidunetdisk/Images/Cracker/40/402CPP/30/11.png)

```cpp
// 异常.cpp : 此文件包含 "main" 函数。程序执行将在此处开始并结束。

#include <iostream>
using namespace std;

class CMyException
{
public:
    CMyException(string strFileName, string strFuncName, int nLine, string strErr) :
        m_strFileName(strFileName),
        m_strFuncName(strFuncName),
        m_nLine(nLine),
        m_strErr(strErr) 
    {}
    string GetFileName() const;
    void SetFileName(string val);
    string GetFuncName() const;
    void SetFuncName(string val);
    int GetLine() const;
    void SetLine(int n);
    string GetErr() const;
    void SetErr(string val);
private:
    string m_strFileName;// 文件名
    string m_strFuncName;// 函数名
    int m_nLine;// 行号
    string m_strErr;// 错误信息
};

class CAddException:public CMyException
{
public:
    CAddException(string strFileName, string strFuncName, int nLine) :
        CMyException(strFileName, strFuncName, nLine, "加法溢出")
    {}
};

void Add()
{
    throw CAddException(__FILE__, __FUNCTION__, __LINE__);
}

void Func()
{
    throw CMyException(__FILE__, __FUNCTION__, __LINE__, "错误");
}

int main()
{
    try
    {
        Add();
        Func();
    }
    catch (const CMyException& e)
    {
        cout << e.GetFileName() << endl
            << e.GetFuncName() << endl
            << e.GetLine() << endl
            << e.GetErr() << endl;
    }

    return 0;
}

string CMyException::GetFileName() const
{
    return m_strFileName;
}

void CMyException::SetFileName(string val)
{
    m_strFileName = val;
}

string CMyException::GetFuncName() const
{
    return m_strFuncName;
}

void CMyException::SetFuncName(string val)
{
    m_strFuncName = val;
}

int CMyException::GetLine() const
{
    return m_nLine;
}

void CMyException::SetLine(int n)
{
    m_nLine = n;
}

string CMyException::GetErr() const
{
    return m_strErr;
}

void CMyException::SetErr(string val)
{
    m_strErr = val;
}
```

## C++官方异常库

![12](https://alist.hmbb313.top/d/Baidunetdisk/Images/Cracker/40/402CPP/30/12.png)

### 只有一个what()方法

![13](https://alist.hmbb313.top/d/Baidunetdisk/Images/Cracker/40/402CPP/30/13.png)

![14](https://alist.hmbb313.top/d/Baidunetdisk/Images/Cracker/40/402CPP/30/14.png)

![15](https://alist.hmbb313.top/d/Baidunetdisk/Images/Cracker/40/402CPP/30/15.png)

### overflow_error是exception的子类

# 智能指针

### 支持CFoo数组,并限制CFoo对象和CFoo数组的一些使用方式

```cpp
// 智能指针.cpp : 此文件包含 "main" 函数。程序执行将在此处开始并结束。

#include <iostream>
#include <memory>
#include <type_traits>
using namespace std;

class CFoo
{
public:
    CFoo(int n):m_n(n) { cout << "CFoo::CFoo()" << endl; }
   ~CFoo() { cout << "CFoo::~CFoo()" << endl; }
   int GetN() const { return m_n; }
   void SetN(int n) { m_n = n; }
private:
    int m_n;
};

template<typename T>
class CPtr
{
public:
    using EteT = remove_extent_t<T>;// 不管是CFoo还是CFoo[],EteT都是CFoo
    CPtr(EteT* p) :m_p(p) {}
    ~CPtr()
    {
        if (is_array_v<T>)// 判断T是否是数组
        {
            delete[] m_p;
        }
        else
        {
            delete m_p;
        }
    }

    // enable_if_t<!if_array__v<CFoo>, int>如果不是CFoo类型，才定义int
    template<typename Ty = T, enable_if_t<!is_array_v<Ty>, int> = 0>
    Ty* operator->()
    {
        return m_p;
    }
    template<typename Ty = T, enable_if_t<!is_array_v<Ty>, int> = 0>
    Ty& operator*()
    {
        return *m_p;
    }
    template<typename Ty = T, enable_if_t<is_array_v<Ty>, int> = 0>
    EteT& operator[](int nIdx)
    {
        return m_p[nIdx];
    }
private:
    EteT* m_p;// 如果传入CFoo[],就变成CFoo[]* m_p;就不对了
};

int main()
{
    shared_ptr<CFoo> ptr(new CFoo(1));
    ptr->SetN(10);
    (*ptr).SetN(11);
    // ptr[0].SetN(13);不支持这样

    shared_ptr<CFoo[]> ptr1(new CFoo[2]{ 1, 3 });
    ptr1[0].SetN(9);
    // ptr1->SetN(10);也不支持
    // (*ptr1).SetN(11);也不支持

    // 相当于对CPP的原始指针操作做了限制

    CPtr<CFoo> ptr2(new CFoo(1));
    ptr2->SetN(10);
    (*ptr2).SetN(11);
    // ptr[0].SetN(13);不支持这样

    CPtr<CFoo[]> ptr3(new CFoo[2]{ 1, 3 });
    ptr3[0].SetN(9);

    return 0;
}
```





